Workbook

Sheet Config
A1: Key | B1: Value
A2: SnapshotDate | B2: 46064

Sheet Episodes
A1: Season | B1: Episode # | C1: Guest
A2: 0 | B2: 0 | C2: Teaser
A3: 1 | B3: 1 | C3: C. De Jaeger
A4: 1 | B4: 2 | C4: T. Dusautoir
A5: 1 | B5: 3 | C5: M. Leboyer
A6: 1 | B6: 4 | C6: T. Cambon
A7: 1 | B7: 5 | C7: M. Cazeneuve
A8: 2 | B8: 6 | C8: J. Debbouze & Dr. Panichelli
A9: 2 | B9: 7 | C9: Prof. Goldman
A10: 2 | B10: 8 | C10: B. Dautzenberg
A11: 2 | B11: 9 | C11: M. Touvier
A12: 2 | B12: 10 | C12: P. Lemoine
A13: 3 | B13: 11 | C13: Maître Wang
... A20: 4 | B20: 18 | C20: Pr. Sofiane Bentifallah

Sheet Summary_By_Season
A1: Season | B1: YT Long Views | C1: YT Long Impressions | D1: YT Shorts Views | E1: YT Shorts Impressions | F1: YT Total Views (Long+Shorts) | G1: Audio DL Total | H1: TikTok Views | I1: Instagram Views | J1: Blog views | K1: LinkedIn Impressions | L1: LinkedIn Likes | M1: LinkedIn Comments | N1: LinkedIn Shares/Reposts
A2: =IFERROR(__xludf.DUMMYFUNCTION("SORT(UNIQUE(FILTER(Episodes!A2:A1000, Episodes!A2:A1000<>"""")))"),0.0) -> 0 | B2: =IF($A2="","",SUMIF(Summary_By_Episode!A:A,$A2,Summary_By_Episode!D:D)) -> 864 | C2: =IF($A2="","",SUMIF(Summary_By_Episode!A:A,$A2,Summary_By_Episode!E:E)) -> 7688 | D2: =IF($A2="","",SUMIF(Summary_By_Episode!A:A,$A2,Summary_By_Episode!H:H)) -> 0 | E2: =IF($A2="","",SUMIF(Summary_By_Episode!A:A,$A2,Summary_By_Episode!I:I)) -> 0 | F2: =B2+D2 -> 864 | G2: =IF($A2="","",SUMIF(Summary_By_Episode!$A:$A,$A2,Summary_By_Episode!$K:$K)) -> 88 | H2: =IF($A2="","",SUMIF(Summary_By_Episode!A:A,$A2,Summary_By_Episode!M:M)) -> 665 | I2: =IF($A2="","",SUMIF(Summary_By_Episode!A:A,$A2,Summary_By_Episode!O:O)) -> 294 | J2: =IF($A2="","",SUMIF(Summary_By_Episode!A:A,$A2,Summary_By_Episode!P:P)) -> 0 | K2: =IF($A2="","",SUMIF(Summary_By_Episode!A:A,$A2,Summary_By_Episode!R:R)) -> 0 | L2: =IF($A2="","",SUMIF(Summary_By_Episode!A:A,$A2,Summary_By_Episode!S:S)) -> 0 | M2: =IF($A2="","",SUMIF(Summary_By_Episode!A:A,$A2,Summary_By_Episode!T:T)) -> 0 | N2: =IF($A2="","",SUMIF(Summary_By_Episode!A:A,$A2,Summary_By_Episode!U:U)) -> 0
A3: =IFERROR(__xludf.DUMMYFUNCTION("""COMPUTED_VALUE"""),1.0) -> 1 | B3: =IF($A3="","",SUMIF(Summary_By_Episode!A:A,$A3,Summary_By_Episode!D:D)) -> 63469 | C3: =IF($A3="","",SUMIF(Summary_By_Episode!A:A,$A3,Summary_By_Episode!E:E)) -> 848631 | D3: =IF($A3="","",SUMIF(Summary_By_Episode!A:A,$A3,Summary_By_Episode!H:H)) -> 171265 | E3: =IF($A3="","",SUMIF(Summary_By_Episode!A:A,$A3,Summary_By_Episode!I:I)) -> 243621 | F3: =B3+D3 -> 234734 | G3: =IF($A3="","",SUMIF(Summary_By_Episode!$A:$A,$A3,Summary_By_Episode!$K:$K)) -> 2776 | H3: =IF($A3="","",SUMIF(Summary_By_Episode!A:A,$A3,Summary_By_Episode!M:M)) -> 146020 | I3: =IF($A3="","",SUMIF(Summary_By_Episode!A:A,$A3,Summary_By_Episode!O:O)) -> 72150 | J3: =IF($A3="","",SUMIF(Summary_By_Episode!A:A,$A3,Summary_By_Episode!P:P)) -> 2694 | K3: =IF($A3="","",SUMIF(Summary_By_Episode!A:A,$A3,Summary_By_Episode!R:R)) -> 0 | L3: =IF($A3="","",SUMIF(Summary_By_Episode!A:A,$A3,Summary_By_Episode!S:S)) -> 0 | M3: =IF($A3="","",SUMIF(Summary_By_Episode!A:A,$A3,Summary_By_Episode!T:T)) -> 0 | N3: =IF($A3="","",SUMIF(Summary_By_Episode!A:A,$A3,Summary_By_Episode!U:U)) -> 0
A4: =IFERROR(__xludf.DUMMYFUNCTION("""COMPUTED_VALUE"""),2.0) -> 2 | B4: =IF($A4="","",SUMIF(Summary_By_Episode!A:A,$A4,Summary_By_Episode!D:D)) -> 150901 | C4: =IF($A4="","",SUMIF(Summary_By_Episode!A:A,$A4,Summary_By_Episode!E:E)) -> 1898599 | D4: =IF($A4="","",SUMIF(Summary_By_Episode!A:A,$A4,Summary_By_Episode!H:H)) -> 347320 | E4: =IF($A4="","",SUMIF(Summary_By_Episode!A:A,$A4,Summary_By_Episode!I:I)) -> 473107 | F4: =B4+D4 -> 498221 | G4: =IF($A4="","",SUMIF(Summary_By_Episode!$A:$A,$A4,Summary_By_Episode!$K:$K)) -> 2798 | H4: =IF($A4="","",SUMIF(Summary_By_Episode!A:A,$A4,Summary_By_Episode!M:M)) -> 54952 | I4: =IF($A4="","",SUMIF(Summary_By_Episode!A:A,$A4,Summary_By_Episode!O:O)) -> 16614 | J4: =IF($A4="","",SUMIF(Summary_By_Episode!A:A,$A4,Summary_By_Episode!P:P)) -> 1524 | K4: =IF($A4="","",SUMIF(Summary_By_Episode!A:A,$A4,Summary_By_Episode!R:R)) -> 0 | L4: =IF($A4="","",SUMIF(Summary_By_Episode!A:A,$A4,Summary_By_Episode!S:S)) -> 0 | M4: =IF($A4="","",SUMIF(Summary_By_Episode!A:A,$A4,Summary_By_Episode!T:T)) -> 0 | N4: =IF($A4="","",SUMIF(Summary_By_Episode!A:A,$A4,Summary_By_Episode!U:U)) -> 0
A5: =IFERROR(__xludf.DUMMYFUNCTION("""COMPUTED_VALUE"""),3.0) -> 3 | B5: =IF($A5="","",SUMIF(Summary_By_Episode!A:A,$A5,Summary_By_Episode!D:D)) -> 188315 | C5: =IF($A5="","",SUMIF(Summary_By_Episode!A:A,$A5,Summary_By_Episode!E:E)) -> 3073636 | D5: =IF($A5="","",SUMIF(Summary_By_Episode!A:A,$A5,Summary_By_Episode!H:H)) -> 32016 | E5: =IF($A5="","",SUMIF(Summary_By_Episode!A:A,$A5,Summary_By_Episode!I:I)) -> 239143 | F5: =B5+D5 -> 220331 | G5: =IF($A5="","",SUMIF(Summary_By_Episode!$A:$A,$A5,Summary_By_Episode!$K:$K)) -> 2790 | H5: =IF($A5="","",SUMIF(Summary_By_Episode!A:A,$A5,Summary_By_Episode!M:M)) -> 10529 | I5: =IF($A5="","",SUMIF(Summary_By_Episode!A:A,$A5,Summary_By_Episode!O:O)) -> 14900 | J5: =IF($A5="","",SUMIF(Summary_By_Episode!A:A,$A5,Summary_By_Episode!P:P)) -> 827 | K5: =IF($A5="","",SUMIF(Summary_By_Episode!A:A,$A5,Summary_By_Episode!R:R)) -> 0 | L5: =IF($A5="","",SUMIF(Summary_By_Episode!A:A,$A5,Summary_By_Episode!S:S)) -> 0 | M5: =IF($A5="","",SUMIF(Summary_By_Episode!A:A,$A5,Summary_By_Episode!T:T)) -> 0 | N5: =IF($A5="","",SUMIF(Summary_By_Episode!A:A,$A5,Summary_By_Episode!U:U)) -> 0
A6: =IFERROR(__xludf.DUMMYFUNCTION("""COMPUTED_VALUE"""),4.0) -> 4 | B6: =IF($A6="","",SUMIF(Summary_By_Episode!A:A,$A6,Summary_By_Episode!D:D)) -> 116927 | C6: =IF($A6="","",SUMIF(Summary_By_Episode!A:A,$A6,Summary_By_Episode!E:E)) -> 1818241 | D6: =IF($A6="","",SUMIF(Summary_By_Episode!A:A,$A6,Summary_By_Episode!H:H)) -> 27025 | E6: =IF($A6="","",SUMIF(Summary_By_Episode!A:A,$A6,Summary_By_Episode!I:I)) -> 70628 | F6: =B6+D6 -> 143952 | G6: =IF($A6="","",SUMIF(Summary_By_Episode!$A:$A,$A6,Summary_By_Episode!$K:$K)) -> 1361 | H6: =IF($A6="","",SUMIF(Summary_By_Episode!A:A,$A6,Summary_By_Episode!M:M)) -> 5374 | I6: =IF($A6="","",SUMIF(Summary_By_Episode!A:A,$A6,Summary_By_Episode!O:O)) -> 12873 | J6: =IF($A6="","",SUMIF(Summary_By_Episode!A:A,$A6,Summary_By_Episode!P:P)) -> 135 | K6: =IF($A6="","",SUMIF(Summary_By_Episode!A:A,$A6,Summary_By_Episode!R:R)) -> 0 | L6: =IF($A6="","",SUMIF(Summary_By_Episode!A:A,$A6,Summary_By_Episode!S:S)) -> 0 | M6: =IF($A6="","",SUMIF(Summary_By_Episode!A:A,$A6,Summary_By_Episode!T:T)) -> 0 | N6: =IF($A6="","",SUMIF(Summary_By_Episode!A:A,$A6,Summary_By_Episode!U:U)) -> 0
B7: =IF($A7="","",SUMIF(Summary_By_Episode!A:A,$A7,Summary_By_Episode!D:D)) | C7: =IF($A7="","",SUMIF(Summary_By_Episode!A:A,$A7,Summary_By_Episode!E:E)) | D7: =IF($A7="","",SUMIF(Summary_By_Episode!A:A,$A7,Summary_By_Episode!H:H)) | E7: =IF($A7="","",SUMIF(Summary_By_Episode!A:A,$A7,Summary_By_Episode!I:I)) | F7: =IF($A7="","",SUMIF(Summary_By_Episode!A:A,$A7,Summary_By_Episode!J:J)) | G7: =IF($A7="","",SUMIF(Summary_By_Episode!A:A,$A7,#REF!)) | H7: =IF($A7="","",SUMIF(Summary_By_Episode!A:A,$A7,Summary_By_Episode!M:M)) | I7: =IF($A7="","",SUMIF(Summary_By_Episode!A:A,$A7,Summary_By_Episode!O:O)) | J7: =IF($A7="","",SUMIF(Summary_By_Episode!A:A,$A7,Summary_By_Episode!P:P)) | K7: =IF($A7="","",SUMIF(Summary_By_Episode!A:A,$A7,Summary_By_Episode!R:R)) | L7: =IF($A7="","",SUMIF(Summary_By_Episode!A:A,$A7,Summary_By_Episode!S:S)) | M7: =IF($A7="","",SUMIF(Summary_By_Episode!A:A,$A7,Summary_By_Episode!T:T)) | N7: =IF($A7="","",SUMIF(Summary_By_Episode!A:A,$A7,Summary_By_Episode!U:U))
B8: =IF($A8="","",SUMIF(Summary_By_Episode!A:A,$A8,Summary_By_Episode!D:D)) | C8: =IF($A8="","",SUMIF(Summary_By_Episode!A:A,$A8,Summary_By_Episode!E:E)) | D8: =IF($A8="","",SUMIF(Summary_By_Episode!A:A,$A8,Summary_By_Episode!H:H)) | E8: =IF($A8="","",SUMIF(Summary_By_Episode!A:A,$A8,Summary_By_Episode!I:I)) | F8: =IF($A8="","",SUMIF(Summary_By_Episode!A:A,$A8,Summary_By_Episode!J:J)) | G8: =IF($A8="","",SUMIF(Summary_By_Episode!A:A,$A8,#REF!)) | H8: =IF($A8="","",SUMIF(Summary_By_Episode!A:A,$A8,Summary_By_Episode!M:M)) | I8: =IF($A8="","",SUMIF(Summary_By_Episode!A:A,$A8,Summary_By_Episode!O:O)) | J8: =IF($A8="","",SUMIF(Summary_By_Episode!A:A,$A8,Summary_By_Episode!P:P)) | K8: =IF($A8="","",SUMIF(Summary_By_Episode!A:A,$A8,Summary_By_Episode!R:R)) | L8: =IF($A8="","",SUMIF(Summary_By_Episode!A:A,$A8,Summary_By_Episode!S:S)) | M8: =IF($A8="","",SUMIF(Summary_By_Episode!A:A,$A8,Summary_By_Episode!T:T)) | N8: =IF($A8="","",SUMIF(Summary_By_Episode!A:A,$A8,Summary_By_Episode!U:U))
B9: =IF($A9="","",SUMIF(Summary_By_Episode!A:A,$A9,Summary_By_Episode!D:D)) | C9: =IF($A9="","",SUMIF(Summary_By_Episode!A:A,$A9,Summary_By_Episode!E:E)) | D9: =IF($A9="","",SUMIF(Summary_By_Episode!A:A,$A9,Summary_By_Episode!H:H)) | E9: =IF($A9="","",SUMIF(Summary_By_Episode!A:A,$A9,Summary_By_Episode!I:I)) | F9: =IF($A9="","",SUMIF(Summary_By_Episode!A:A,$A9,Summary_By_Episode!J:J)) | G9: =IF($A9="","",SUMIF(Summary_By_Episode!A:A,$A9,#REF!)) | H9: =IF($A9="","",SUMIF(Summary_By_Episode!A:A,$A9,Summary_By_Episode!M:M)) | I9: =IF($A9="","",SUMIF(Summary_By_Episode!A:A,$A9,Summary_By_Episode!O:O)) | J9: =IF($A9="","",SUMIF(Summary_By_Episode!A:A,$A9,Summary_By_Episode!P:P)) | K9: =IF($A9="","",SUMIF(Summary_By_Episode!A:A,$A9,Summary_By_Episode!R:R)) | L9: =IF($A9="","",SUMIF(Summary_By_Episode!A:A,$A9,Summary_By_Episode!S:S)) | M9: =IF($A9="","",SUMIF(Summary_By_Episode!A:A,$A9,Summary_By_Episode!T:T)) | N9: =IF($A9="","",SUMIF(Summary_By_Episode!A:A,$A9,Summary_By_Episode!U:U))
B10: =IF($A10="","",SUMIF(Summary_By_Episode!A:A,$A10,Summary_By_Episode!D:D)) | C10: =IF($A10="","",SUMIF(Summary_By_Episode!A:A,$A10,Summary_By_Episode!E:E)) | D10: =IF($A10="","",SUMIF(Summary_By_Episode!A:A,$A10,Summary_By_Episode!H:H)) | E10: =IF($A10="","",SUMIF(Summary_By_Episode!A:A,$A10,Summary_By_Episode!I:I)) | F10: =IF($A10="","",SUMIF(Summary_By_Episode!A:A,$A10,Summary_By_Episode!J:J)) | G10: =IF($A10="","",SUMIF(Summary_By_Episode!A:A,$A10,#REF!)) | H10: =IF($A10="","",SUMIF(Summary_By_Episode!A:A,$A10,Summary_By_Episode!M:M)) | I10: =IF($A10="","",SUMIF(Summary_By_Episode!A:A,$A10,Summary_By_Episode!O:O)) | J10: =IF($A10="","",SUMIF(Summary_By_Episode!A:A,$A10,Summary_By_Episode!P:P)) | K10: =IF($A10="","",SUMIF(Summary_By_Episode!A:A,$A10,Summary_By_Episode!R:R)) | L10: =IF($A10="","",SUMIF(Summary_By_Episode!A:A,$A10,Summary_By_Episode!S:S)) | M10: =IF($A10="","",SUMIF(Summary_By_Episode!A:A,$A10,Summary_By_Episode!T:T)) | N10: =IF($A10="","",SUMIF(Summary_By_Episode!A:A,$A10,Summary_By_Episode!U:U))
B11: =IF($A11="","",SUMIF(Summary_By_Episode!A:A,$A11,Summary_By_Episode!D:D)) | C11: =IF($A11="","",SUMIF(Summary_By_Episode!A:A,$A11,Summary_By_Episode!E:E)) | D11: =IF($A11="","",SUMIF(Summary_By_Episode!A:A,$A11,Summary_By_Episode!H:H)) | E11: =IF($A11="","",SUMIF(Summary_By_Episode!A:A,$A11,Summary_By_Episode!I:I)) | F11: =IF($A11="","",SUMIF(Summary_By_Episode!A:A,$A11,Summary_By_Episode!J:J)) | G11: =IF($A11="","",SUMIF(Summary_By_Episode!A:A,$A11,#REF!)) | H11: =IF($A11="","",SUMIF(Summary_By_Episode!A:A,$A11,Summary_By_Episode!M:M)) | I11: =IF($A11="","",SUMIF(Summary_By_Episode!A:A,$A11,Summary_By_Episode!O:O)) | J11: =IF($A11="","",SUMIF(Summary_By_Episode!A:A,$A11,Summary_By_Episode!P:P)) | K11: =IF($A11="","",SUMIF(Summary_By_Episode!A:A,$A11,Summary_By_Episode!R:R)) | L11: =IF($A11="","",SUMIF(Summary_By_Episode!A:A,$A11,Summary_By_Episode!S:S)) | M11: =IF($A11="","",SUMIF(Summary_By_Episode!A:A,$A11,Summary_By_Episode!T:T)) | N11: =IF($A11="","",SUMIF(Summary_By_Episode!A:A,$A11,Summary_By_Episode!U:U))
B12: =IF($A12="","",SUMIF(Summary_By_Episode!A:A,$A12,Summary_By_Episode!D:D)) | C12: =IF($A12="","",SUMIF(Summary_By_Episode!A:A,$A12,Summary_By_Episode!E:E)) | D12: =IF($A12="","",SUMIF(Summary_By_Episode!A:A,$A12,Summary_By_Episode!H:H)) | E12: =IF($A12="","",SUMIF(Summary_By_Episode!A:A,$A12,Summary_By_Episode!I:I)) | F12: =IF($A12="","",SUMIF(Summary_By_Episode!A:A,$A12,Summary_By_Episode!J:J)) | G12: =IF($A12="","",SUMIF(Summary_By_Episode!A:A,$A12,#REF!)) | H12: =IF($A12="","",SUMIF(Summary_By_Episode!A:A,$A12,Summary_By_Episode!M:M)) | I12: =IF($A12="","",SUMIF(Summary_By_Episode!A:A,$A12,Summary_By_Episode!O:O)) | J12: =IF($A12="","",SUMIF(Summary_By_Episode!A:A,$A12,Summary_By_Episode!P:P)) | K12: =IF($A12="","",SUMIF(Summary_By_Episode!A:A,$A12,Summary_By_Episode!R:R)) | L12: =IF($A12="","",SUMIF(Summary_By_Episode!A:A,$A12,Summary_By_Episode!S:S)) | M12: =IF($A12="","",SUMIF(Summary_By_Episode!A:A,$A12,Summary_By_Episode!T:T)) | N12: =IF($A12="","",SUMIF(Summary_By_Episode!A:A,$A12,Summary_By_Episode!U:U))
B13: =IF($A13="","",SUMIF(Summary_By_Episode!A:A,$A13,Summary_By_Episode!D:D)) | C13: =IF($A13="","",SUMIF(Summary_By_Episode!A:A,$A13,Summary_By_Episode!E:E)) | D13: =IF($A13="","",SUMIF(Summary_By_Episode!A:A,$A13,Summary_By_Episode!H:H)) | E13: =IF($A13="","",SUMIF(Summary_By_Episode!A:A,$A13,Summary_By_Episode!I:I)) | F13: =IF($A13="","",SUMIF(Summary_By_Episode!A:A,$A13,Summary_By_Episode!J:J)) | G13: =IF($A13="","",SUMIF(Summary_By_Episode!A:A,$A13,#REF!)) | H13: =IF($A13="","",SUMIF(Summary_By_Episode!A:A,$A13,Summary_By_Episode!M:M)) | I13: =IF($A13="","",SUMIF(Summary_By_Episode!A:A,$A13,Summary_By_Episode!O:O)) | J13: =IF($A13="","",SUMIF(Summary_By_Episode!A:A,$A13,Summary_By_Episode!P:P)) | K13: =IF($A13="","",SUMIF(Summary_By_Episode!A:A,$A13,Summary_By_Episode!R:R)) | L13: =IF($A13="","",SUMIF(Summary_By_Episode!A:A,$A13,Summary_By_Episode!S:S)) | M13: =IF($A13="","",SUMIF(Summary_By_Episode!A:A,$A13,Summary_By_Episode!T:T)) | N13: =IF($A13="","",SUMIF(Summary_By_Episode!A:A,$A13,Summary_By_Episode!U:U))
B14: =IF($A14="","",SUMIF(Summary_By_Episode!A:A,$A14,Summary_By_Episode!D:D)) | C14: =IF($A14="","",SUMIF(Summary_By_Episode!A:A,$A14,Summary_By_Episode!E:E)) | D14: =IF($A14="","",SUMIF(Summary_By_Episode!A:A,$A14,Summary_By_Episode!H:H)) | E14: =IF($A14="","",SUMIF(Summary_By_Episode!A:A,$A14,Summary_By_Episode!I:I)) | F14: =IF($A14="","",SUMIF(Summary_By_Episode!A:A,$A14,Summary_By_Episode!J:J)) | G14: =IF($A14="","",SUMIF(Summary_By_Episode!A:A,$A14,#REF!)) | H14: =IF($A14="","",SUMIF(Summary_By_Episode!A:A,$A14,Summary_By_Episode!M:M)) | I14: =IF($A14="","",SUMIF(Summary_By_Episode!A:A,$A14,Summary_By_Episode!O:O)) | J14: =IF($A14="","",SUMIF(Summary_By_Episode!A:A,$A14,Summary_By_Episode!P:P)) | K14: =IF($A14="","",SUMIF(Summary_By_Episode!A:A,$A14,Summary_By_Episode!R:R)) | L14: =IF($A14="","",SUMIF(Summary_By_Episode!A:A,$A14,Summary_By_Episode!S:S)) | M14: =IF($A14="","",SUMIF(Summary_By_Episode!A:A,$A14,Summary_By_Episode!T:T)) | N14: =IF($A14="","",SUMIF(Summary_By_Episode!A:A,$A14,Summary_By_Episode!U:U))
B15: =IF($A15="","",SUMIF(Summary_By_Episode!A:A,$A15,Summary_By_Episode!D:D)) | C15: =IF($A15="","",SUMIF(Summary_By_Episode!A:A,$A15,Summary_By_Episode!E:E)) | D15: =IF($A15="","",SUMIF(Summary_By_Episode!A:A,$A15,Summary_By_Episode!H:H)) | E15: =IF($A15="","",SUMIF(Summary_By_Episode!A:A,$A15,Summary_By_Episode!I:I)) | F15: =IF($A15="","",SUMIF(Summary_By_Episode!A:A,$A15,Summary_By_Episode!J:J)) | G15: =IF($A15="","",SUMIF(Summary_By_Episode!A:A,$A15,#REF!)) | H15: =IF($A15="","",SUMIF(Summary_By_Episode!A:A,$A15,Summary_By_Episode!M:M)) | I15: =IF($A15="","",SUMIF(Summary_By_Episode!A:A,$A15,Summary_By_Episode!O:O)) | J15: =IF($A15="","",SUMIF(Summary_By_Episode!A:A,$A15,Summary_By_Episode!P:P)) | K15: =IF($A15="","",SUMIF(Summary_By_Episode!A:A,$A15,Summary_By_Episode!R:R)) | L15: =IF($A15="","",SUMIF(Summary_By_Episode!A:A,$A15,Summary_By_Episode!S:S)) | M15: =IF($A15="","",SUMIF(Summary_By_Episode!A:A,$A15,Summary_By_Episode!T:T)) | N15: =IF($A15="","",SUMIF(Summary_By_Episode!A:A,$A15,Summary_By_Episode!U:U))
B16: =IF($A16="","",SUMIF(Summary_By_Episode!A:A,$A16,Summary_By_Episode!D:D)) | C16: =IF($A16="","",SUMIF(Summary_By_Episode!A:A,$A16,Summary_By_Episode!E:E)) | D16: =IF($A16="","",SUMIF(Summary_By_Episode!A:A,$A16,Summary_By_Episode!H:H)) | E16: =IF($A16="","",SUMIF(Summary_By_Episode!A:A,$A16,Summary_By_Episode!I:I)) | F16: =IF($A16="","",SUMIF(Summary_By_Episode!A:A,$A16,Summary_By_Episode!J:J)) | G16: =IF($A16="","",SUMIF(Summary_By_Episode!A:A,$A16,#REF!)) | H16: =IF($A16="","",SUMIF(Summary_By_Episode!A:A,$A16,Summary_By_Episode!M:M)) | I16: =IF($A16="","",SUMIF(Summary_By_Episode!A:A,$A16,Summary_By_Episode!O:O)) | J16: =IF($A16="","",SUMIF(Summary_By_Episode!A:A,$A16,Summary_By_Episode!P:P)) | K16: =IF($A16="","",SUMIF(Summary_By_Episode!A:A,$A16,Summary_By_Episode!R:R)) | L16: =IF($A16="","",SUMIF(Summary_By_Episode!A:A,$A16,Summary_By_Episode!S:S)) | M16: =IF($A16="","",SUMIF(Summary_By_Episode!A:A,$A16,Summary_By_Episode!T:T)) | N16: =IF($A16="","",SUMIF(Summary_By_Episode!A:A,$A16,Summary_By_Episode!U:U))
B17: =IF($A17="","",SUMIF(Summary_By_Episode!A:A,$A17,Summary_By_Episode!D:D)) | C17: =IF($A17="","",SUMIF(Summary_By_Episode!A:A,$A17,Summary_By_Episode!E:E)) | D17: =IF($A17="","",SUMIF(Summary_By_Episode!A:A,$A17,Summary_By_Episode!H:H)) | E17: =IF($A17="","",SUMIF(Summary_By_Episode!A:A,$A17,Summary_By_Episode!I:I)) | F17: =IF($A17="","",SUMIF(Summary_By_Episode!A:A,$A17,Summary_By_Episode!J:J)) | G17: =IF($A17="","",SUMIF(Summary_By_Episode!A:A,$A17,#REF!)) | H17: =IF($A17="","",SUMIF(Summary_By_Episode!A:A,$A17,Summary_By_Episode!M:M)) | I17: =IF($A17="","",SUMIF(Summary_By_Episode!A:A,$A17,Summary_By_Episode!O:O)) | J17: =IF($A17="","",SUMIF(Summary_By_Episode!A:A,$A17,Summary_By_Episode!P:P)) | K17: =IF($A17="","",SUMIF(Summary_By_Episode!A:A,$A17,Summary_By_Episode!R:R)) | L17: =IF($A17="","",SUMIF(Summary_By_Episode!A:A,$A17,Summary_By_Episode!S:S)) | M17: =IF($A17="","",SUMIF(Summary_By_Episode!A:A,$A17,Summary_By_Episode!T:T)) | N17: =IF($A17="","",SUMIF(Summary_By_Episode!A:A,$A17,Summary_By_Episode!U:U))
B18: =IF($A18="","",SUMIF(Summary_By_Episode!A:A,$A18,Summary_By_Episode!D:D)) | C18: =IF($A18="","",SUMIF(Summary_By_Episode!A:A,$A18,Summary_By_Episode!E:E)) | D18: =IF($A18="","",SUMIF(Summary_By_Episode!A:A,$A18,Summary_By_Episode!H:H)) | E18: =IF($A18="","",SUMIF(Summary_By_Episode!A:A,$A18,Summary_By_Episode!I:I)) | F18: =IF($A18="","",SUMIF(Summary_By_Episode!A:A,$A18,Summary_By_Episode!J:J)) | G18: =IF($A18="","",SUMIF(Summary_By_Episode!A:A,$A18,#REF!)) | H18: =IF($A18="","",SUMIF(Summary_By_Episode!A:A,$A18,Summary_By_Episode!M:M)) | I18: =IF($A18="","",SUMIF(Summary_By_Episode!A:A,$A18,Summary_By_Episode!O:O)) | J18: =IF($A18="","",SUMIF(Summary_By_Episode!A:A,$A18,Summary_By_Episode!P:P)) | K18: =IF($A18="","",SUMIF(Summary_By_Episode!A:A,$A18,Summary_By_Episode!R:R)) | L18: =IF($A18="","",SUMIF(Summary_By_Episode!A:A,$A18,Summary_By_Episode!S:S)) | M18: =IF($A18="","",SUMIF(Summary_By_Episode!A:A,$A18,Summary_By_Episode!T:T)) | N18: =IF($A18="","",SUMIF(Summary_By_Episode!A:A,$A18,Summary_By_Episode!U:U))
... B51: =IF($A51="","",SUMIF(Summary_By_Episode!A:A,$A51,Summary_By_Episode!D:D)) | C51: =IF($A51="","",SUMIF(Summary_By_Episode!A:A,$A51,Summary_By_Episode!E:E)) | D51: =IF($A51="","",SUMIF(Summary_By_Episode!A:A,$A51,Summary_By_Episode!H:H)) | E51: =IF($A51="","",SUMIF(Summary_By_Episode!A:A,$A51,Summary_By_Episode!I:I)) | F51: =IF($A51="","",SUMIF(Summary_By_Episode!A:A,$A51,Summary_By_Episode!J:J)) | G51: =IF($A51="","",SUMIF(Summary_By_Episode!A:A,$A51,#REF!)) | H51: =IF($A51="","",SUMIF(Summary_By_Episode!A:A,$A51,Summary_By_Episode!M:M)) | I51: =IF($A51="","",SUMIF(Summary_By_Episode!A:A,$A51,Summary_By_Episode!O:O)) | J51: =IF($A51="","",SUMIF(Summary_By_Episode!A:A,$A51,Summary_By_Episode!P:P)) | K51: =IF($A51="","",SUMIF(Summary_By_Episode!A:A,$A51,Summary_By_Episode!R:R)) | L51: =IF($A51="","",SUMIF(Summary_By_Episode!A:A,$A51,Summary_By_Episode!S:S)) | M51: =IF($A51="","",SUMIF(Summary_By_Episode!A:A,$A51,Summary_By_Episode!T:T)) | N51: =IF($A51="","",SUMIF(Summary_By_Episode!A:A,$A51,Summary_By_Episode!U:U))

Sheet Summary_By_Episode
A1: Season | B1: Episode # | C1: Guest | D1: Total YT Long Views | E1: Total YT Long Impressions | F1: YT Long CTR% | G1: # YT Shorts | H1: YT Shorts Views | I1: YT Shorts Impressions | J1: YT Total Views (Long+Shorts) | K1: Total audio downloads | L1: TikTok Posts (#) | M1: TikTok Views | N1: Instagram Posts (#) | O1: Instagram Views | P1: Website Views | Q1: LinkedIn Posts (#) | R1: LinkedIn Impressions | S1: LinkedIn Likes | T1: LinkedIn Comments | U1: LinkedIn Shares/Reposts
A2: {=IF(Episodes!A2:A1000="","",Episodes!A2:A1000)} -> 0 | B2: {=IF(Episodes!B2:B1000="","",Episodes!B2:B1000)} -> 0 | C2: {=IF(Episodes!A2:A1000="","",Episodes!C2:C1000)} -> Teaser | D2: =IF($A2="","",SUMIFS(YouTube_Long!G:G,YouTube_Long!A:A,$A2,YouTube_Long!B:B,$B2)) -> 864 | E2: =IF($A2="","",SUMIFS(YouTube_Long!H:H,YouTube_Long!A:A,$A2,YouTube_Long!B:B,$B2)) -> 7688 | F2: =IF($A2="","",SUMIFS(YouTube_Long!I:I,YouTube_Long!A:A,$A2,YouTube_Long!B:B,$B2)) -> 0.051 | G2: =YouTube_Shorts!D2 -> 0 | H2: =IF($A2="","",SUMIFS(YouTube_Shorts!F:F,YouTube_Shorts!A:A,$A2,YouTube_Shorts!B:B,$B2)) -> 0 | I2: =IF($A2="","",SUMIFS(YouTube_Shorts!G:G,YouTube_Shorts!A:A,$A2,YouTube_Shorts!B:B,$B2)) -> 0 | J2: =IF($A2="","",$D2+$H2) -> 864 | K2: =Audio!F2 -> 88 | L2: =TikTok_Posts!E2 -> 1 | M2: =IF($A2="","",SUMIFS(TikTok_Posts!G:G,TikTok_Posts!A:A,$A2,TikTok_Posts!B:B,$B2)) -> 665 | N2: =Instagram_Posts!D2 -> 1 | O2: =IF($A2="","",SUMIFS(Instagram_Posts!E:E,Instagram_Posts!A:A,$A2,Instagram_Posts!B:B,$B2)) -> 294 | P2: =Blog!E2 | Q2: =IF($A2="","",COUNTIFS(LinkedIn_Posts!A:A,$A2,LinkedIn_Posts!B:B,$B2)) -> 1 | R2: =IF($A2="","",SUMIFS(LinkedIn_Posts!F:F,LinkedIn_Posts!A:A,$A2,LinkedIn_Posts!B:B,$B2)) -> 0 | S2: =IF($A2="","",SUMIFS(LinkedIn_Posts!G:G,LinkedIn_Posts!A:A,$A2,LinkedIn_Posts!B:B,$B2)) -> 0 | T2: =IF($A2="","",SUMIFS(LinkedIn_Posts!H:H,LinkedIn_Posts!A:A,$A2,LinkedIn_Posts!B:B,$B2)) -> 0 | U2: =IF($A2="","",SUMIFS(LinkedIn_Posts!I:I,LinkedIn_Posts!A:A,$A2,LinkedIn_Posts!B:B,$B2)) -> 0
A3: 1 | B3: 1 | C3: C. De Jaeger | D3: =IF($A3="","",SUMIFS(YouTube_Long!G:G,YouTube_Long!A:A,$A3,YouTube_Long!B:B,$B3)) -> 53630 | E3: =IF($A3="","",SUMIFS(YouTube_Long!H:H,YouTube_Long!A:A,$A3,YouTube_Long!B:B,$B3)) -> 703036 | F3: =IF($A3="","",SUMIFS(YouTube_Long!I:I,YouTube_Long!A:A,$A3,YouTube_Long!B:B,$B3)) -> 0.05 | G3: =YouTube_Shorts!D3 -> 1 | H3: =sum(YouTube_Shorts!F3,YouTube_Shorts!I3,YouTube_Shorts!L3,YouTube_Shorts!O3,YouTube_Shorts!R3,YouTube_Shorts!U3,YouTube_Shorts!X3,YouTube_Shorts!AA3) -> 105597 | I3: =sum(YouTube_Shorts!G3,YouTube_Shorts!J3,YouTube_Shorts!M3,YouTube_Shorts!P3,YouTube_Shorts!S3,YouTube_Shorts!V3,YouTube_Shorts!Y3,YouTube_Shorts!AB3) -> 213651 | J3: =IF($A3="","",$D3+$H3) -> 159227 | K3: =Audio!F3 -> 954 | L3: =TikTok_Posts!E3 -> 1 | M3: =IF($A3="","",SUMIFS(TikTok_Posts!G:G,TikTok_Posts!A:A,$A3,TikTok_Posts!B:B,$B3)) -> 779 | N3: =Instagram_Posts!D3 -> 1 | O3: =IF($A3="","",SUMIFS(Instagram_Posts!E:E,Instagram_Posts!A:A,$A3,Instagram_Posts!B:B,$B3)) -> 1400 | P3: =Blog!E3 -> 1534 | Q3: =IF($A3="","",COUNTIFS(LinkedIn_Posts!A:A,$A3,LinkedIn_Posts!B:B,$B3)) -> 1 | R3: =IF($A3="","",SUMIFS(LinkedIn_Posts!F:F,LinkedIn_Posts!A:A,$A3,LinkedIn_Posts!B:B,$B3)) -> 0 | S3: =IF($A3="","",SUMIFS(LinkedIn_Posts!G:G,LinkedIn_Posts!A:A,$A3,LinkedIn_Posts!B:B,$B3)) -> 0 | T3: =IF($A3="","",SUMIFS(LinkedIn_Posts!H:H,LinkedIn_Posts!A:A,$A3,LinkedIn_Posts!B:B,$B3)) -> 0 | U3: =IF($A3="","",SUMIFS(LinkedIn_Posts!I:I,LinkedIn_Posts!A:A,$A3,LinkedIn_Posts!B:B,$B3)) -> 0
A4: 1 | B4: 2 | C4: T. Dusautoir | D4: =IF($A4="","",SUMIFS(YouTube_Long!G:G,YouTube_Long!A:A,$A4,YouTube_Long!B:B,$B4)) -> 1301 | E4: =IF($A4="","",SUMIFS(YouTube_Long!H:H,YouTube_Long!A:A,$A4,YouTube_Long!B:B,$B4)) -> 14793 | F4: =IF($A4="","",SUMIFS(YouTube_Long!I:I,YouTube_Long!A:A,$A4,YouTube_Long!B:B,$B4)) -> 0.042 | G4: =YouTube_Shorts!D4 -> 3 | H4: =sum(YouTube_Shorts!F4,YouTube_Shorts!I4,YouTube_Shorts!L4,YouTube_Shorts!O4,YouTube_Shorts!R4,YouTube_Shorts!U4,YouTube_Shorts!X4,YouTube_Shorts!AA4) -> 63167 | I4: =sum(YouTube_Shorts!G4,YouTube_Shorts!J4,YouTube_Shorts!M4,YouTube_Shorts!P4,YouTube_Shorts!S4,YouTube_Shorts!V4,YouTube_Shorts!Y4,YouTube_Shorts!AB4) -> 18991 | J4: =IF($A4="","",$D4+$H4) -> 64468 | K4: =Audio!F4 -> 476 | L4: =TikTok_Posts!E4 -> 6 | M4: =IF($A4="","",SUMIFS(TikTok_Posts!G:G,TikTok_Posts!A:A,$A4,TikTok_Posts!B:B,$B4)) -> 142488 | N4: =Instagram_Posts!D4 -> 5 | O4: =IF($A4="","",SUMIFS(Instagram_Posts!E:E,Instagram_Posts!A:A,$A4,Instagram_Posts!B:B,$B4)) -> 67864 | P4: =Blog!E4 -> 195 | Q4: =IF($A4="","",COUNTIFS(LinkedIn_Posts!A:A,$A4,LinkedIn_Posts!B:B,$B4)) -> 1 | R4: =IF($A4="","",SUMIFS(LinkedIn_Posts!F:F,LinkedIn_Posts!A:A,$A4,LinkedIn_Posts!B:B,$B4)) -> 0 | S4: =IF($A4="","",SUMIFS(LinkedIn_Posts!G:G,LinkedIn_Posts!A:A,$A4,LinkedIn_Posts!B:B,$B4)) -> 0 | T4: =IF($A4="","",SUMIFS(LinkedIn_Posts!H:H,LinkedIn_Posts!A:A,$A4,LinkedIn_Posts!B:B,$B4)) -> 0 | U4: =IF($A4="","",SUMIFS(LinkedIn_Posts!I:I,LinkedIn_Posts!A:A,$A4,LinkedIn_Posts!B:B,$B4)) -> 0
A5: 1 | B5: 3 | C5: M. Leboyer | D5: =IF($A5="","",SUMIFS(YouTube_Long!G:G,YouTube_Long!A:A,$A5,YouTube_Long!B:B,$B5)) -> 6722 | E5: =IF($A5="","",SUMIFS(YouTube_Long!H:H,YouTube_Long!A:A,$A5,YouTube_Long!B:B,$B5)) -> 110531 | F5: =IF($A5="","",SUMIFS(YouTube_Long!I:I,YouTube_Long!A:A,$A5,YouTube_Long!B:B,$B5)) -> 0.038 | G5: =YouTube_Shorts!D5 -> 1 | H5: =sum(YouTube_Shorts!F5,YouTube_Shorts!I5,YouTube_Shorts!L5,YouTube_Shorts!O5,YouTube_Shorts!R5,YouTube_Shorts!U5,YouTube_Shorts!X5,YouTube_Shorts!AA5) -> 1256 | I5: =sum(YouTube_Shorts!G5,YouTube_Shorts!J5,YouTube_Shorts!M5,YouTube_Shorts!P5,YouTube_Shorts!S5,YouTube_Shorts!V5,YouTube_Shorts!Y5,YouTube_Shorts!AB5) -> 5730 | J5: =IF($A5="","",$D5+$H5) -> 7978 | K5: =Audio!F5 -> 438 | L5: =TikTok_Posts!E5 -> 1 | M5: =IF($A5="","",SUMIFS(TikTok_Posts!G:G,TikTok_Posts!A:A,$A5,TikTok_Posts!B:B,$B5)) -> 1426 | N5: =Instagram_Posts!D5 -> 1 | O5: =IF($A5="","",SUMIFS(Instagram_Posts!E:E,Instagram_Posts!A:A,$A5,Instagram_Posts!B:B,$B5)) -> 867 | P5: =Blog!E5 -> 433 | Q5: =IF($A5="","",COUNTIFS(LinkedIn_Posts!A:A,$A5,LinkedIn_Posts!B:B,$B5)) -> 1 | R5: =IF($A5="","",SUMIFS(LinkedIn_Posts!F:F,LinkedIn_Posts!A:A,$A5,LinkedIn_Posts!B:B,$B5)) -> 0 | S5: =IF($A5="","",SUMIFS(LinkedIn_Posts!G:G,LinkedIn_Posts!A:A,$A5,LinkedIn_Posts!B:B,$B5)) -> 0 | T5: =IF($A5="","",SUMIFS(LinkedIn_Posts!H:H,LinkedIn_Posts!A:A,$A5,LinkedIn_Posts!B:B,$B5)) -> 0 | U5: =IF($A5="","",SUMIFS(LinkedIn_Posts!I:I,LinkedIn_Posts!A:A,$A5,LinkedIn_Posts!B:B,$B5)) -> 0
A6: 1 | B6: 4 | C6: T. Cambon | D6: =IF($A6="","",SUMIFS(YouTube_Long!G:G,YouTube_Long!A:A,$A6,YouTube_Long!B:B,$B6)) -> 644 | E6: =IF($A6="","",SUMIFS(YouTube_Long!H:H,YouTube_Long!A:A,$A6,YouTube_Long!B:B,$B6)) -> 9997 | F6: =IF($A6="","",SUMIFS(YouTube_Long!I:I,YouTube_Long!A:A,$A6,YouTube_Long!B:B,$B6)) -> 0.023 | G6: =YouTube_Shorts!D6 -> 1 | H6: =sum(YouTube_Shorts!F6,YouTube_Shorts!I6,YouTube_Shorts!L6,YouTube_Shorts!O6,YouTube_Shorts!R6,YouTube_Shorts!U6,YouTube_Shorts!X6,YouTube_Shorts!AA6) -> 1245 | I6: =sum(YouTube_Shorts!G6,YouTube_Shorts!J6,YouTube_Shorts!M6,YouTube_Shorts!P6,YouTube_Shorts!S6,YouTube_Shorts!V6,YouTube_Shorts!Y6,YouTube_Shorts!AB6) -> 5249 | J6: =IF($A6="","",$D6+$H6) -> 1889 | K6: =Audio!F6 -> 351 | L6: =TikTok_Posts!E6 -> 1 | M6: =IF($A6="","",SUMIFS(TikTok_Posts!G:G,TikTok_Posts!A:A,$A6,TikTok_Posts!B:B,$B6)) -> 1327 | N6: =Instagram_Posts!D6 -> 2 | O6: =IF($A6="","",SUMIFS(Instagram_Posts!E:E,Instagram_Posts!A:A,$A6,Instagram_Posts!B:B,$B6)) -> 2019 | P6: =Blog!E6 -> 150 | Q6: =IF($A6="","",COUNTIFS(LinkedIn_Posts!A:A,$A6,LinkedIn_Posts!B:B,$B6)) -> 1 | R6: =IF($A6="","",SUMIFS(LinkedIn_Posts!F:F,LinkedIn_Posts!A:A,$A6,LinkedIn_Posts!B:B,$B6)) -> 0 | S6: =IF($A6="","",SUMIFS(LinkedIn_Posts!G:G,LinkedIn_Posts!A:A,$A6,LinkedIn_Posts!B:B,$B6)) -> 0 | T6: =IF($A6="","",SUMIFS(LinkedIn_Posts!H:H,LinkedIn_Posts!A:A,$A6,LinkedIn_Posts!B:B,$B6)) -> 0 | U6: =IF($A6="","",SUMIFS(LinkedIn_Posts!I:I,LinkedIn_Posts!A:A,$A6,LinkedIn_Posts!B:B,$B6)) -> 0
A7: 1 | B7: 5 | C7: M. Cazeneuve | D7: =IF($A7="","",SUMIFS(YouTube_Long!G:G,YouTube_Long!A:A,$A7,YouTube_Long!B:B,$B7)) -> 1172 | E7: =IF($A7="","",SUMIFS(YouTube_Long!H:H,YouTube_Long!A:A,$A7,YouTube_Long!B:B,$B7)) -> 10274 | F7: =IF($A7="","",SUMIFS(YouTube_Long!I:I,YouTube_Long!A:A,$A7,YouTube_Long!B:B,$B7)) -> 0.051 | G7: =YouTube_Shorts!D7 -> 0 | H7: =sum(YouTube_Shorts!F7,YouTube_Shorts!I7,YouTube_Shorts!L7,YouTube_Shorts!O7,YouTube_Shorts!R7,YouTube_Shorts!U7,YouTube_Shorts!X7,YouTube_Shorts!AA7) -> 0 | I7: =sum(YouTube_Shorts!G7,YouTube_Shorts!J7,YouTube_Shorts!M7,YouTube_Shorts!P7,YouTube_Shorts!S7,YouTube_Shorts!V7,YouTube_Shorts!Y7,YouTube_Shorts!AB7) -> 0 | J7: =IF($A7="","",$D7+$H7) -> 1172 | K7: =Audio!F7 -> 557 | L7: =TikTok_Posts!E7 -> 0 | M7: =IF($A7="","",SUMIFS(TikTok_Posts!G:G,TikTok_Posts!A:A,$A7,TikTok_Posts!B:B,$B7)) -> 0 | N7: =Instagram_Posts!D7 -> 0 | O7: =IF($A7="","",SUMIFS(Instagram_Posts!E:E,Instagram_Posts!A:A,$A7,Instagram_Posts!B:B,$B7)) -> 0 | P7: =Blog!E7 -> 382 | Q7: =IF($A7="","",COUNTIFS(LinkedIn_Posts!A:A,$A7,LinkedIn_Posts!B:B,$B7)) -> 1 | R7: =IF($A7="","",SUMIFS(LinkedIn_Posts!F:F,LinkedIn_Posts!A:A,$A7,LinkedIn_Posts!B:B,$B7)) -> 0 | S7: =IF($A7="","",SUMIFS(LinkedIn_Posts!G:G,LinkedIn_Posts!A:A,$A7,LinkedIn_Posts!B:B,$B7)) -> 0 | T7: =IF($A7="","",SUMIFS(LinkedIn_Posts!H:H,LinkedIn_Posts!A:A,$A7,LinkedIn_Posts!B:B,$B7)) -> 0 | U7: =IF($A7="","",SUMIFS(LinkedIn_Posts!I:I,LinkedIn_Posts!A:A,$A7,LinkedIn_Posts!B:B,$B7)) -> 0
A8: 2 | B8: 6 | C8: J. Debbouze & Dr. Panichelli | D8: =IF($A8="","",SUMIFS(YouTube_Long!G:G,YouTube_Long!A:A,$A8,YouTube_Long!B:B,$B8)) -> 2256 | E8: =IF($A8="","",SUMIFS(YouTube_Long!H:H,YouTube_Long!A:A,$A8,YouTube_Long!B:B,$B8)) -> 31232 | F8: =IF($A8="","",SUMIFS(YouTube_Long!I:I,YouTube_Long!A:A,$A8,YouTube_Long!B:B,$B8)) -> 0.039 | G8: =YouTube_Shorts!D8 -> 2 | H8: =sum(YouTube_Shorts!F8,YouTube_Shorts!I8,YouTube_Shorts!L8,YouTube_Shorts!O8,YouTube_Shorts!R8,YouTube_Shorts!U8,YouTube_Shorts!X8,YouTube_Shorts!AA8) -> 124810 | I8: =sum(YouTube_Shorts!G8,YouTube_Shorts!J8,YouTube_Shorts!M8,YouTube_Shorts!P8,YouTube_Shorts!S8,YouTube_Shorts!V8,YouTube_Shorts!Y8,YouTube_Shorts!AB8) -> 18015 | J8: =IF($A8="","",$D8+$H8) -> 127066 | K8: =Audio!F8 -> 435 | L8: =TikTok_Posts!E8 -> 6 | M8: =IF($A8="","",SUMIFS(TikTok_Posts!G:G,TikTok_Posts!A:A,$A8,TikTok_Posts!B:B,$B8)) -> 30352 | N8: =Instagram_Posts!D8 -> 5 | O8: =IF($A8="","",SUMIFS(Instagram_Posts!E:E,Instagram_Posts!A:A,$A8,Instagram_Posts!B:B,$B8)) -> 10500 | P8: =Blog!E8 -> 227 | Q8: =IF($A8="","",COUNTIFS(LinkedIn_Posts!A:A,$A8,LinkedIn_Posts!B:B,$B8)) -> 1 | R8: =IF($A8="","",SUMIFS(LinkedIn_Posts!F:F,LinkedIn_Posts!A:A,$A8,LinkedIn_Posts!B:B,$B8)) -> 0 | S8: =IF($A8="","",SUMIFS(LinkedIn_Posts!G:G,LinkedIn_Posts!A:A,$A8,LinkedIn_Posts!B:B,$B8)) -> 0 | T8: =IF($A8="","",SUMIFS(LinkedIn_Posts!H:H,LinkedIn_Posts!A:A,$A8,LinkedIn_Posts!B:B,$B8)) -> 0 | U8: =IF($A8="","",SUMIFS(LinkedIn_Posts!I:I,LinkedIn_Posts!A:A,$A8,LinkedIn_Posts!B:B,$B8)) -> 0
A9: 2 | B9: 7 | C9: Prof. Goldman | D9: =IF($A9="","",SUMIFS(YouTube_Long!G:G,YouTube_Long!A:A,$A9,YouTube_Long!B:B,$B9)) -> 277 | E9: =IF($A9="","",SUMIFS(YouTube_Long!H:H,YouTube_Long!A:A,$A9,YouTube_Long!B:B,$B9)) -> 9638 | F9: =IF($A9="","",SUMIFS(YouTube_Long!I:I,YouTube_Long!A:A,$A9,YouTube_Long!B:B,$B9)) -> 0.016 | G9: =YouTube_Shorts!D9 -> 0 | H9: =sum(YouTube_Shorts!F9,YouTube_Shorts!I9,YouTube_Shorts!L9,YouTube_Shorts!O9,YouTube_Shorts!R9,YouTube_Shorts!U9,YouTube_Shorts!X9,YouTube_Shorts!AA9) -> 0 | I9: =sum(YouTube_Shorts!G9,YouTube_Shorts!J9,YouTube_Shorts!M9,YouTube_Shorts!P9,YouTube_Shorts!S9,YouTube_Shorts!V9,YouTube_Shorts!Y9,YouTube_Shorts!AB9) -> 0 | J9: =IF($A9="","",$D9+$H9) -> 277 | K9: =Audio!F9 -> 353 | L9: =TikTok_Posts!E9 -> 0 | M9: =IF($A9="","",SUMIFS(TikTok_Posts!G:G,TikTok_Posts!A:A,$A9,TikTok_Posts!B:B,$B9)) -> 0 | N9: =Instagram_Posts!D9 -> 0 | O9: =IF($A9="","",SUMIFS(Instagram_Posts!E:E,Instagram_Posts!A:A,$A9,Instagram_Posts!B:B,$B9)) -> 0 | P9: =Blog!E9 -> 246 | Q9: =IF($A9="","",COUNTIFS(LinkedIn_Posts!A:A,$A9,LinkedIn_Posts!B:B,$B9)) -> 1 | R9: =IF($A9="","",SUMIFS(LinkedIn_Posts!F:F,LinkedIn_Posts!A:A,$A9,LinkedIn_Posts!B:B,$B9)) -> 0 | S9: =IF($A9="","",SUMIFS(LinkedIn_Posts!G:G,LinkedIn_Posts!A:A,$A9,LinkedIn_Posts!B:B,$B9)) -> 0 | T9: =IF($A9="","",SUMIFS(LinkedIn_Posts!H:H,LinkedIn_Posts!A:A,$A9,LinkedIn_Posts!B:B,$B9)) -> 0 | U9: =IF($A9="","",SUMIFS(LinkedIn_Posts!I:I,LinkedIn_Posts!A:A,$A9,LinkedIn_Posts!B:B,$B9)) -> 0
A10: 2 | B10: 8 | C10: B. Dautzenberg | D10: =IF($A10="","",SUMIFS(YouTube_Long!G:G,YouTube_Long!A:A,$A10,YouTube_Long!B:B,$B10)) -> 29838 | E10: =IF($A10="","",SUMIFS(YouTube_Long!H:H,YouTube_Long!A:A,$A10,YouTube_Long!B:B,$B10)) -> 301238 | F10: =IF($A10="","",SUMIFS(YouTube_Long!I:I,YouTube_Long!A:A,$A10,YouTube_Long!B:B,$B10)) -> 0.06 | G10: =YouTube_Shorts!D10 -> 4 | H10: =sum(YouTube_Shorts!F10,YouTube_Shorts!I10,YouTube_Shorts!L10,YouTube_Shorts!O10,YouTube_Shorts!R10,YouTube_Shorts!U10,YouTube_Shorts!X10,YouTube_Shorts!AA10) -> 152524 | I10: =sum(YouTube_Shorts!G10,YouTube_Shorts!J10,YouTube_Shorts!M10,YouTube_Shorts!P10,YouTube_Shorts!S10,YouTube_Shorts!V10,YouTube_Shorts!Y10,YouTube_Shorts!AB10) -> 260432 | J10: =IF($A10="","",$D10+$H10) -> 182362 | K10: =Audio!F10 -> 912 | L10: =TikTok_Posts!E10 -> 2 | M10: =IF($A10="","",SUMIFS(TikTok_Posts!G:G,TikTok_Posts!A:A,$A10,TikTok_Posts!B:B,$B10)) -> 8383 | N10: =Instagram_Posts!D10 -> 2 | O10: =IF($A10="","",SUMIFS(Instagram_Posts!E:E,Instagram_Posts!A:A,$A10,Instagram_Posts!B:B,$B10)) -> 1931 | P10: =Blog!E10 -> 622 | Q10: =IF($A10="","",COUNTIFS(LinkedIn_Posts!A:A,$A10,LinkedIn_Posts!B:B,$B10)) -> 1 | R10: =IF($A10="","",SUMIFS(LinkedIn_Posts!F:F,LinkedIn_Posts!A:A,$A10,LinkedIn_Posts!B:B,$B10)) -> 0 | S10: =IF($A10="","",SUMIFS(LinkedIn_Posts!G:G,LinkedIn_Posts!A:A,$A10,LinkedIn_Posts!B:B,$B10)) -> 0 | T10: =IF($A10="","",SUMIFS(LinkedIn_Posts!H:H,LinkedIn_Posts!A:A,$A10,LinkedIn_Posts!B:B,$B10)) -> 0 | U10: =IF($A10="","",SUMIFS(LinkedIn_Posts!I:I,LinkedIn_Posts!A:A,$A10,LinkedIn_Posts!B:B,$B10)) -> 0
A11: 2 | B11: 9 | C11: M. Touvier | D11: =IF($A11="","",SUMIFS(YouTube_Long!G:G,YouTube_Long!A:A,$A11,YouTube_Long!B:B,$B11)) -> 8563 | E11: =IF($A11="","",SUMIFS(YouTube_Long!H:H,YouTube_Long!A:A,$A11,YouTube_Long!B:B,$B11)) -> 98078 | F11: =IF($A11="","",SUMIFS(YouTube_Long!I:I,YouTube_Long!A:A,$A11,YouTube_Long!B:B,$B11)) -> 0.052 | G11: =YouTube_Shorts!D11 -> 2 | H11: =sum(YouTube_Shorts!F11,YouTube_Shorts!I11,YouTube_Shorts!L11,YouTube_Shorts!O11,YouTube_Shorts!R11,YouTube_Shorts!U11,YouTube_Shorts!X11,YouTube_Shorts!AA11) -> 13049 | I11: =sum(YouTube_Shorts!G11,YouTube_Shorts!J11,YouTube_Shorts!M11,YouTube_Shorts!P11,YouTube_Shorts!S11,YouTube_Shorts!V11,YouTube_Shorts!Y11,YouTube_Shorts!AB11) -> 11417 | J11: =IF($A11="","",$D11+$H11) -> 21612 | K11: =Audio!F11 -> 461 | L11: =TikTok_Posts!E11 -> 0 | M11: =IF($A11="","",SUMIFS(TikTok_Posts!G:G,TikTok_Posts!A:A,$A11,TikTok_Posts!B:B,$B11)) -> 0 | N11: =Instagram_Posts!D11 -> 2 | O11: =IF($A11="","",SUMIFS(Instagram_Posts!E:E,Instagram_Posts!A:A,$A11,Instagram_Posts!B:B,$B11)) -> 1783 | P11: =Blog!E11 -> 206 | Q11: =IF($A11="","",COUNTIFS(LinkedIn_Posts!A:A,$A11,LinkedIn_Posts!B:B,$B11)) -> 1 | R11: =IF($A11="","",SUMIFS(LinkedIn_Posts!F:F,LinkedIn_Posts!A:A,$A11,LinkedIn_Posts!B:B,$B11)) -> 0 | S11: =IF($A11="","",SUMIFS(LinkedIn_Posts!G:G,LinkedIn_Posts!A:A,$A11,LinkedIn_Posts!B:B,$B11)) -> 0 | T11: =IF($A11="","",SUMIFS(LinkedIn_Posts!H:H,LinkedIn_Posts!A:A,$A11,LinkedIn_Posts!B:B,$B11)) -> 0 | U11: =IF($A11="","",SUMIFS(LinkedIn_Posts!I:I,LinkedIn_Posts!A:A,$A11,LinkedIn_Posts!B:B,$B11)) -> 0
A12: 2 | B12: 10 | C12: P. Lemoine | D12: =IF($A12="","",SUMIFS(YouTube_Long!G:G,YouTube_Long!A:A,$A12,YouTube_Long!B:B,$B12)) -> 109967 | E12: =IF($A12="","",SUMIFS(YouTube_Long!H:H,YouTube_Long!A:A,$A12,YouTube_Long!B:B,$B12)) -> 1458413 | F12: =IF($A12="","",SUMIFS(YouTube_Long!I:I,YouTube_Long!A:A,$A12,YouTube_Long!B:B,$B12)) -> 0.053 | G12: =YouTube_Shorts!D12 -> 5 | H12: =sum(YouTube_Shorts!F12,YouTube_Shorts!I12,YouTube_Shorts!L12,YouTube_Shorts!O12,YouTube_Shorts!R12,YouTube_Shorts!U12,YouTube_Shorts!X12,YouTube_Shorts!AA12) -> 56937 | I12: =sum(YouTube_Shorts!G12,YouTube_Shorts!J12,YouTube_Shorts!M12,YouTube_Shorts!P12,YouTube_Shorts!S12,YouTube_Shorts!V12,YouTube_Shorts!Y12,YouTube_Shorts!AB12) -> 183243 | J12: =IF($A12="","",$D12+$H12) -> 166904 | K12: =Audio!F12 -> 637 | L12: =TikTok_Posts!E12 -> 4 | M12: =IF($A12="","",SUMIFS(TikTok_Posts!G:G,TikTok_Posts!A:A,$A12,TikTok_Posts!B:B,$B12)) -> 16217 | N12: =Instagram_Posts!D12 -> 2 | O12: =IF($A12="","",SUMIFS(Instagram_Posts!E:E,Instagram_Posts!A:A,$A12,Instagram_Posts!B:B,$B12)) -> 2400 | P12: =Blog!E12 -> 223 | Q12: =IF($A12="","",COUNTIFS(LinkedIn_Posts!A:A,$A12,LinkedIn_Posts!B:B,$B12)) -> 1 | R12: =IF($A12="","",SUMIFS(LinkedIn_Posts!F:F,LinkedIn_Posts!A:A,$A12,LinkedIn_Posts!B:B,$B12)) -> 0 | S12: =IF($A12="","",SUMIFS(LinkedIn_Posts!G:G,LinkedIn_Posts!A:A,$A12,LinkedIn_Posts!B:B,$B12)) -> 0 | T12: =IF($A12="","",SUMIFS(LinkedIn_Posts!H:H,LinkedIn_Posts!A:A,$A12,LinkedIn_Posts!B:B,$B12)) -> 0 | U12: =IF($A12="","",SUMIFS(LinkedIn_Posts!I:I,LinkedIn_Posts!A:A,$A12,LinkedIn_Posts!B:B,$B12)) -> 0
A13: 3 | B13: 11 | C13: Maître Wang | D13: =IF($A13="","",SUMIFS(YouTube_Long!G:G,YouTube_Long!A:A,$A13,YouTube_Long!B:B,$B13)) -> 163250 | E13: =IF($A13="","",SUMIFS(YouTube_Long!H:H,YouTube_Long!A:A,$A13,YouTube_Long!B:B,$B13)) -> 2769055 | F13: =IF($A13="","",SUMIFS(YouTube_Long!I:I,YouTube_Long!A:A,$A13,YouTube_Long!B:B,$B13)) -> 0.037 | G13: =YouTube_Shorts!D13 -> 3 | H13: =sum(YouTube_Shorts!F13,YouTube_Shorts!I13,YouTube_Shorts!L13,YouTube_Shorts!O13,YouTube_Shorts!R13,YouTube_Shorts!U13,YouTube_Shorts!X13,YouTube_Shorts!AA13) -> 13893 | I13: =sum(YouTube_Shorts!G13,YouTube_Shorts!J13,YouTube_Shorts!M13,YouTube_Shorts!P13,YouTube_Shorts!S13,YouTube_Shorts!V13,YouTube_Shorts!Y13,YouTube_Shorts!AB13) -> 174703 | J13: =IF($A13="","",$D13+$H13) -> 177143 | K13: =Audio!F13 -> 647 | L13: =TikTok_Posts!E13 -> 4 | M13: =IF($A13="","",SUMIFS(TikTok_Posts!G:G,TikTok_Posts!A:A,$A13,TikTok_Posts!B:B,$B13)) -> 2257 | N13: =Instagram_Posts!D13 -> 5 | O13: =IF($A13="","",SUMIFS(Instagram_Posts!E:E,Instagram_Posts!A:A,$A13,Instagram_Posts!B:B,$B13)) -> 3500 | P13: =Blog!E13 -> 114 | Q13: =IF($A13="","",COUNTIFS(LinkedIn_Posts!A:A,$A13,LinkedIn_Posts!B:B,$B13)) -> 1 | R13: =IF($A13="","",SUMIFS(LinkedIn_Posts!F:F,LinkedIn_Posts!A:A,$A13,LinkedIn_Posts!B:B,$B13)) -> 0 | S13: =IF($A13="","",SUMIFS(LinkedIn_Posts!G:G,LinkedIn_Posts!A:A,$A13,LinkedIn_Posts!B:B,$B13)) -> 0 | T13: =IF($A13="","",SUMIFS(LinkedIn_Posts!H:H,LinkedIn_Posts!A:A,$A13,LinkedIn_Posts!B:B,$B13)) -> 0 | U13: =IF($A13="","",SUMIFS(LinkedIn_Posts!I:I,LinkedIn_Posts!A:A,$A13,LinkedIn_Posts!B:B,$B13)) -> 0
A14: 3 | B14: 12 | C14: B. Gallix | D14: =IF($A14="","",SUMIFS(YouTube_Long!G:G,YouTube_Long!A:A,$A14,YouTube_Long!B:B,$B14)) -> 21443 | E14: =IF($A14="","",SUMIFS(YouTube_Long!H:H,YouTube_Long!A:A,$A14,YouTube_Long!B:B,$B14)) -> 267489 | F14: =IF($A14="","",SUMIFS(YouTube_Long!I:I,YouTube_Long!A:A,$A14,YouTube_Long!B:B,$B14)) -> 0.059 | G14: =YouTube_Shorts!D14 -> 1 | H14: =sum(YouTube_Shorts!F14,YouTube_Shorts!I14,YouTube_Shorts!L14,YouTube_Shorts!O14,YouTube_Shorts!R14,YouTube_Shorts!U14,YouTube_Shorts!X14,YouTube_Shorts!AA14) -> 3851 | I14: =sum(YouTube_Shorts!G14,YouTube_Shorts!J14,YouTube_Shorts!M14,YouTube_Shorts!P14,YouTube_Shorts!S14,YouTube_Shorts!V14,YouTube_Shorts!Y14,YouTube_Shorts!AB14) -> 28390 | J14: =IF($A14="","",$D14+$H14) -> 25294 | K14: =Audio!F14 -> 694 | L14: =TikTok_Posts!E14 -> 0 | M14: =IF($A14="","",SUMIFS(TikTok_Posts!G:G,TikTok_Posts!A:A,$A14,TikTok_Posts!B:B,$B14)) -> 0 | N14: =Instagram_Posts!D14 -> 3 | O14: =IF($A14="","",SUMIFS(Instagram_Posts!E:E,Instagram_Posts!A:A,$A14,Instagram_Posts!B:B,$B14)) -> 2000 | P14: =Blog!E14 -> 163 | Q14: =IF($A14="","",COUNTIFS(LinkedIn_Posts!A:A,$A14,LinkedIn_Posts!B:B,$B14)) -> 1 | R14: =IF($A14="","",SUMIFS(LinkedIn_Posts!F:F,LinkedIn_Posts!A:A,$A14,LinkedIn_Posts!B:B,$B14)) -> 0 | S14: =IF($A14="","",SUMIFS(LinkedIn_Posts!G:G,LinkedIn_Posts!A:A,$A14,LinkedIn_Posts!B:B,$B14)) -> 0 | T14: =IF($A14="","",SUMIFS(LinkedIn_Posts!H:H,LinkedIn_Posts!A:A,$A14,LinkedIn_Posts!B:B,$B14)) -> 0 | U14: =IF($A14="","",SUMIFS(LinkedIn_Posts!I:I,LinkedIn_Posts!A:A,$A14,LinkedIn_Posts!B:B,$B14)) -> 0
... A20: 4 | B20: 18 | C20: Pr. Sofiane Bentifallah | D20: =IF($A20="","",SUMIFS(YouTube_Long!G:G,YouTube_Long!A:A,$A20,YouTube_Long!B:B,$B20)) -> 520 | E20: =IF($A20="","",SUMIFS(YouTube_Long!H:H,YouTube_Long!A:A,$A20,YouTube_Long!B:B,$B20)) -> 11083 | F20: =IF($A20="","",SUMIFS(YouTube_Long!I:I,YouTube_Long!A:A,$A20,YouTube_Long!B:B,$B20)) -> 0.025 | G20: =YouTube_Shorts!D20 -> 0 | H20: =sum(YouTube_Shorts!F20,YouTube_Shorts!I20,YouTube_Shorts!L20,YouTube_Shorts!O20,YouTube_Shorts!R20,YouTube_Shorts!U20,YouTube_Shorts!X20,YouTube_Shorts!AA20) -> 0 | I20: =sum(YouTube_Shorts!G20,YouTube_Shorts!J20,YouTube_Shorts!M20,YouTube_Shorts!P20,YouTube_Shorts!S20,YouTube_Shorts!V20,YouTube_Shorts!Y20,YouTube_Shorts!AB20) -> 0 | J20: =IF($A20="","",$D20+$H20) -> 520 | K20: =Audio!F20 -> 392 | L20: =TikTok_Posts!E20 -> 0 | M20: =IF($A20="","",SUMIFS(TikTok_Posts!G:G,TikTok_Posts!A:A,$A20,TikTok_Posts!B:B,$B20)) -> 0 | N20: =Instagram_Posts!D20 -> 0 | O20: =IF($A20="","",SUMIFS(Instagram_Posts!E:E,Instagram_Posts!A:A,$A20,Instagram_Posts!B:B,$B20)) -> 0 | P20: =Blog!E20 | Q20: =IF($A20="","",COUNTIFS(LinkedIn_Posts!A:A,$A20,LinkedIn_Posts!B:B,$B20)) -> 1 | R20: =IF($A20="","",SUMIFS(LinkedIn_Posts!F:F,LinkedIn_Posts!A:A,$A20,LinkedIn_Posts!B:B,$B20)) -> 0 | S20: =IF($A20="","",SUMIFS(LinkedIn_Posts!G:G,LinkedIn_Posts!A:A,$A20,LinkedIn_Posts!B:B,$B20)) -> 0 | T20: =IF($A20="","",SUMIFS(LinkedIn_Posts!H:H,LinkedIn_Posts!A:A,$A20,LinkedIn_Posts!B:B,$B20)) -> 0 | U20: =IF($A20="","",SUMIFS(LinkedIn_Posts!I:I,LinkedIn_Posts!A:A,$A20,LinkedIn_Posts!B:B,$B20)) -> 0
D21: =IF($A21="","",SUMIFS(YouTube_Long!G:G,YouTube_Long!A:A,$A21,YouTube_Long!B:B,$B21)) | E21: =IF($A21="","",SUMIFS(YouTube_Long!H:H,YouTube_Long!A:A,$A21,YouTube_Long!B:B,$B21)) | F21: =IF($A21="","",SUMIFS(YouTube_Long!I:I,YouTube_Long!A:A,$A21,YouTube_Long!B:B,$B21)) | G21: =IF($A21="","",COUNTIFS(YouTube_Shorts!A:A,$A21,YouTube_Shorts!B:B,$B21)) | H21: =IF($A21="","",SUMIFS(YouTube_Shorts!F:F,YouTube_Shorts!A:A,$A21,YouTube_Shorts!B:B,$B21)) | I21: =IF($A21="","",SUMIFS(YouTube_Shorts!G:G,YouTube_Shorts!A:A,$A21,YouTube_Shorts!B:B,$B21)) | J21: =IF($A21="","",$D21+$H21) | K21: =Audio!F21 | L21: =IF($A21="","",COUNTIFS(TikTok_Posts!A:A,$A21,TikTok_Posts!B:B,$B21)) | M21: =IF($A21="","",SUMIFS(TikTok_Posts!E:E,TikTok_Posts!A:A,$A21,TikTok_Posts!B:B,$B21)) | N21: =IF($A21="","",COUNTIFS(Instagram_Posts!A:A,$A21,Instagram_Posts!B:B,$B21)) | O21: =IF($A21="","",SUMIFS(Instagram_Posts!E:E,Instagram_Posts!A:A,$A21,Instagram_Posts!B:B,$B21)) | P21: =IF($A21="","",SUMIFS(Blog!E:E,Blog!B:B,$A21,Blog!C:C,$B21)) | Q21: =IF($A21="","",COUNTIFS(LinkedIn_Posts!A:A,$A21,LinkedIn_Posts!B:B,$B21)) | R21: =IF($A21="","",SUMIFS(LinkedIn_Posts!F:F,LinkedIn_Posts!A:A,$A21,LinkedIn_Posts!B:B,$B21)) | S21: =IF($A21="","",SUMIFS(LinkedIn_Posts!G:G,LinkedIn_Posts!A:A,$A21,LinkedIn_Posts!B:B,$B21)) | T21: =IF($A21="","",SUMIFS(LinkedIn_Posts!H:H,LinkedIn_Posts!A:A,$A21,LinkedIn_Posts!B:B,$B21)) | U21: =IF($A21="","",SUMIFS(LinkedIn_Posts!I:I,LinkedIn_Posts!A:A,$A21,LinkedIn_Posts!B:B,$B21))
D22: =IF($A22="","",SUMIFS(YouTube_Long!G:G,YouTube_Long!A:A,$A22,YouTube_Long!B:B,$B22)) | E22: =IF($A22="","",SUMIFS(YouTube_Long!H:H,YouTube_Long!A:A,$A22,YouTube_Long!B:B,$B22)) | F22: =IF($A22="","",SUMIFS(YouTube_Long!I:I,YouTube_Long!A:A,$A22,YouTube_Long!B:B,$B22)) | G22: =IF($A22="","",COUNTIFS(YouTube_Shorts!A:A,$A22,YouTube_Shorts!B:B,$B22)) | H22: =IF($A22="","",SUMIFS(YouTube_Shorts!F:F,YouTube_Shorts!A:A,$A22,YouTube_Shorts!B:B,$B22)) | J22: =IF($A22="","",$D22+$H22) | K22: =IF($A22="","",SUMIFS(Audio!D:D,Audio!A:A,$A22,Audio!B:B,$B22)) | L22: =IF($A22="","",COUNTIFS(TikTok_Posts!A:A,$A22,TikTok_Posts!B:B,$B22)) | M22: =IF($A22="","",SUMIFS(TikTok_Posts!E:E,TikTok_Posts!A:A,$A22,TikTok_Posts!B:B,$B22)) | N22: =IF($A22="","",COUNTIFS(Instagram_Posts!A:A,$A22,Instagram_Posts!B:B,$B22)) | O22: =IF($A22="","",SUMIFS(Instagram_Posts!E:E,Instagram_Posts!A:A,$A22,Instagram_Posts!B:B,$B22)) | P22: =IF($A22="","",SUMIFS(Blog!E:E,Blog!B:B,$A22,Blog!C:C,$B22)) | Q22: =IF($A22="","",COUNTIFS(LinkedIn_Posts!A:A,$A22,LinkedIn_Posts!B:B,$B22)) | R22: =IF($A22="","",SUMIFS(LinkedIn_Posts!F:F,LinkedIn_Posts!A:A,$A22,LinkedIn_Posts!B:B,$B22)) | S22: =IF($A22="","",SUMIFS(LinkedIn_Posts!G:G,LinkedIn_Posts!A:A,$A22,LinkedIn_Posts!B:B,$B22)) | T22: =IF($A22="","",SUMIFS(LinkedIn_Posts!H:H,LinkedIn_Posts!A:A,$A22,LinkedIn_Posts!B:B,$B22)) | U22: =IF($A22="","",SUMIFS(LinkedIn_Posts!I:I,LinkedIn_Posts!A:A,$A22,LinkedIn_Posts!B:B,$B22))
D23: =IF($A23="","",SUMIFS(YouTube_Long!G:G,YouTube_Long!A:A,$A23,YouTube_Long!B:B,$B23)) | E23: =IF($A23="","",SUMIFS(YouTube_Long!H:H,YouTube_Long!A:A,$A23,YouTube_Long!B:B,$B23)) | F23: =IF($A23="","",SUMIFS(YouTube_Long!I:I,YouTube_Long!A:A,$A23,YouTube_Long!B:B,$B23)) | G23: =IF($A23="","",COUNTIFS(YouTube_Shorts!A:A,$A23,YouTube_Shorts!B:B,$B23)) | H23: =IF($A23="","",SUMIFS(YouTube_Shorts!F:F,YouTube_Shorts!A:A,$A23,YouTube_Shorts!B:B,$B23)) | J23: =IF($A23="","",$D23+$H23) | L23: =IF($A23="","",COUNTIFS(TikTok_Posts!A:A,$A23,TikTok_Posts!B:B,$B23)) | M23: =IF($A23="","",SUMIFS(TikTok_Posts!E:E,TikTok_Posts!A:A,$A23,TikTok_Posts!B:B,$B23)) | N23: =IF($A23="","",COUNTIFS(Instagram_Posts!A:A,$A23,Instagram_Posts!B:B,$B23)) | O23: =IF($A23="","",SUMIFS(Instagram_Posts!E:E,Instagram_Posts!A:A,$A23,Instagram_Posts!B:B,$B23)) | P23: =IF($A23="","",SUMIFS(Blog!E:E,Blog!B:B,$A23,Blog!C:C,$B23)) | Q23: =IF($A23="","",COUNTIFS(LinkedIn_Posts!A:A,$A23,LinkedIn_Posts!B:B,$B23)) | R23: =IF($A23="","",SUMIFS(LinkedIn_Posts!F:F,LinkedIn_Posts!A:A,$A23,LinkedIn_Posts!B:B,$B23)) | S23: =IF($A23="","",SUMIFS(LinkedIn_Posts!G:G,LinkedIn_Posts!A:A,$A23,LinkedIn_Posts!B:B,$B23)) | T23: =IF($A23="","",SUMIFS(LinkedIn_Posts!H:H,LinkedIn_Posts!A:A,$A23,LinkedIn_Posts!B:B,$B23)) | U23: =IF($A23="","",SUMIFS(LinkedIn_Posts!I:I,LinkedIn_Posts!A:A,$A23,LinkedIn_Posts!B:B,$B23))
D24: =IF($A24="","",SUMIFS(YouTube_Long!G:G,YouTube_Long!A:A,$A24,YouTube_Long!B:B,$B24)) | E24: =IF($A24="","",SUMIFS(YouTube_Long!H:H,YouTube_Long!A:A,$A24,YouTube_Long!B:B,$B24)) | F24: =IF($A24="","",SUMIFS(YouTube_Long!I:I,YouTube_Long!A:A,$A24,YouTube_Long!B:B,$B24)) | G24: =IF($A24="","",COUNTIFS(YouTube_Shorts!A:A,$A24,YouTube_Shorts!B:B,$B24)) | H24: =IF($A24="","",SUMIFS(YouTube_Shorts!F:F,YouTube_Shorts!A:A,$A24,YouTube_Shorts!B:B,$B24)) | I24: =IF($A24="","",SUMIFS(YouTube_Shorts!G:G,YouTube_Shorts!A:A,$A24,YouTube_Shorts!B:B,$B24)) | J24: =IF($A24="","",$D24+$H24) | K24: =IF($A24="","",SUMIFS(Audio!D:D,Audio!A:A,$A24,Audio!B:B,$B24)) | L24: =IF($A24="","",COUNTIFS(TikTok_Posts!A:A,$A24,TikTok_Posts!B:B,$B24)) | M24: =IF($A24="","",SUMIFS(TikTok_Posts!E:E,TikTok_Posts!A:A,$A24,TikTok_Posts!B:B,$B24)) | N24: =IF($A24="","",COUNTIFS(Instagram_Posts!A:A,$A24,Instagram_Posts!B:B,$B24)) | O24: =IF($A24="","",SUMIFS(Instagram_Posts!E:E,Instagram_Posts!A:A,$A24,Instagram_Posts!B:B,$B24)) | P24: =IF($A24="","",SUMIFS(Blog!E:E,Blog!B:B,$A24,Blog!C:C,$B24)) | Q24: =IF($A24="","",COUNTIFS(LinkedIn_Posts!A:A,$A24,LinkedIn_Posts!B:B,$B24)) | R24: =IF($A24="","",SUMIFS(LinkedIn_Posts!F:F,LinkedIn_Posts!A:A,$A24,LinkedIn_Posts!B:B,$B24)) | S24: =IF($A24="","",SUMIFS(LinkedIn_Posts!G:G,LinkedIn_Posts!A:A,$A24,LinkedIn_Posts!B:B,$B24)) | T24: =IF($A24="","",SUMIFS(LinkedIn_Posts!H:H,LinkedIn_Posts!A:A,$A24,LinkedIn_Posts!B:B,$B24)) | U24: =IF($A24="","",SUMIFS(LinkedIn_Posts!I:I,LinkedIn_Posts!A:A,$A24,LinkedIn_Posts!B:B,$B24))
D25: =IF($A25="","",SUMIFS(YouTube_Long!G:G,YouTube_Long!A:A,$A25,YouTube_Long!B:B,$B25)) | E25: =IF($A25="","",SUMIFS(YouTube_Long!H:H,YouTube_Long!A:A,$A25,YouTube_Long!B:B,$B25)) | F25: =IF($A25="","",SUMIFS(YouTube_Long!I:I,YouTube_Long!A:A,$A25,YouTube_Long!B:B,$B25)) | G25: =IF($A25="","",COUNTIFS(YouTube_Shorts!A:A,$A25,YouTube_Shorts!B:B,$B25)) | H25: =IF($A25="","",SUMIFS(YouTube_Shorts!F:F,YouTube_Shorts!A:A,$A25,YouTube_Shorts!B:B,$B25)) | I25: =IF($A25="","",SUMIFS(YouTube_Shorts!G:G,YouTube_Shorts!A:A,$A25,YouTube_Shorts!B:B,$B25)) | J25: =IF($A25="","",$D25+$H25) | K25: =IF($A25="","",SUMIFS(Audio!D:D,Audio!A:A,$A25,Audio!B:B,$B25)) | L25: =IF($A25="","",COUNTIFS(TikTok_Posts!A:A,$A25,TikTok_Posts!B:B,$B25)) | M25: =IF($A25="","",SUMIFS(TikTok_Posts!E:E,TikTok_Posts!A:A,$A25,TikTok_Posts!B:B,$B25)) | N25: =IF($A25="","",COUNTIFS(Instagram_Posts!A:A,$A25,Instagram_Posts!B:B,$B25)) | O25: =IF($A25="","",SUMIFS(Instagram_Posts!E:E,Instagram_Posts!A:A,$A25,Instagram_Posts!B:B,$B25)) | P25: =IF($A25="","",SUMIFS(Blog!E:E,Blog!B:B,$A25,Blog!C:C,$B25)) | Q25: =IF($A25="","",COUNTIFS(LinkedIn_Posts!A:A,$A25,LinkedIn_Posts!B:B,$B25)) | R25: =IF($A25="","",SUMIFS(LinkedIn_Posts!F:F,LinkedIn_Posts!A:A,$A25,LinkedIn_Posts!B:B,$B25)) | S25: =IF($A25="","",SUMIFS(LinkedIn_Posts!G:G,LinkedIn_Posts!A:A,$A25,LinkedIn_Posts!B:B,$B25)) | T25: =IF($A25="","",SUMIFS(LinkedIn_Posts!H:H,LinkedIn_Posts!A:A,$A25,LinkedIn_Posts!B:B,$B25)) | U25: =IF($A25="","",SUMIFS(LinkedIn_Posts!I:I,LinkedIn_Posts!A:A,$A25,LinkedIn_Posts!B:B,$B25))
D26: =IF($A26="","",SUMIFS(YouTube_Long!G:G,YouTube_Long!A:A,$A26,YouTube_Long!B:B,$B26)) | E26: =IF($A26="","",SUMIFS(YouTube_Long!H:H,YouTube_Long!A:A,$A26,YouTube_Long!B:B,$B26)) | F26: =IF($A26="","",SUMIFS(YouTube_Long!I:I,YouTube_Long!A:A,$A26,YouTube_Long!B:B,$B26)) | G26: =IF($A26="","",COUNTIFS(YouTube_Shorts!A:A,$A26,YouTube_Shorts!B:B,$B26)) | H26: =IF($A26="","",SUMIFS(YouTube_Shorts!F:F,YouTube_Shorts!A:A,$A26,YouTube_Shorts!B:B,$B26)) | I26: =IF($A26="","",SUMIFS(YouTube_Shorts!G:G,YouTube_Shorts!A:A,$A26,YouTube_Shorts!B:B,$B26)) | J26: =IF($A26="","",$D26+$H26) | K26: =IF($A26="","",SUMIFS(Audio!D:D,Audio!A:A,$A26,Audio!B:B,$B26)) | L26: =IF($A26="","",COUNTIFS(TikTok_Posts!A:A,$A26,TikTok_Posts!B:B,$B26)) | M26: =IF($A26="","",SUMIFS(TikTok_Posts!E:E,TikTok_Posts!A:A,$A26,TikTok_Posts!B:B,$B26)) | N26: =IF($A26="","",COUNTIFS(Instagram_Posts!A:A,$A26,Instagram_Posts!B:B,$B26)) | O26: =IF($A26="","",SUMIFS(Instagram_Posts!E:E,Instagram_Posts!A:A,$A26,Instagram_Posts!B:B,$B26)) | P26: =IF($A26="","",SUMIFS(Blog!E:E,Blog!B:B,$A26,Blog!C:C,$B26)) | Q26: =IF($A26="","",COUNTIFS(LinkedIn_Posts!A:A,$A26,LinkedIn_Posts!B:B,$B26)) | R26: =IF($A26="","",SUMIFS(LinkedIn_Posts!F:F,LinkedIn_Posts!A:A,$A26,LinkedIn_Posts!B:B,$B26)) | S26: =IF($A26="","",SUMIFS(LinkedIn_Posts!G:G,LinkedIn_Posts!A:A,$A26,LinkedIn_Posts!B:B,$B26)) | T26: =IF($A26="","",SUMIFS(LinkedIn_Posts!H:H,LinkedIn_Posts!A:A,$A26,LinkedIn_Posts!B:B,$B26)) | U26: =IF($A26="","",SUMIFS(LinkedIn_Posts!I:I,LinkedIn_Posts!A:A,$A26,LinkedIn_Posts!B:B,$B26))
D27: =IF($A27="","",SUMIFS(YouTube_Long!G:G,YouTube_Long!A:A,$A27,YouTube_Long!B:B,$B27)) | E27: =IF($A27="","",SUMIFS(YouTube_Long!H:H,YouTube_Long!A:A,$A27,YouTube_Long!B:B,$B27)) | F27: =IF($A27="","",SUMIFS(YouTube_Long!I:I,YouTube_Long!A:A,$A27,YouTube_Long!B:B,$B27)) | G27: =IF($A27="","",COUNTIFS(YouTube_Shorts!A:A,$A27,YouTube_Shorts!B:B,$B27)) | H27: =IF($A27="","",SUMIFS(YouTube_Shorts!F:F,YouTube_Shorts!A:A,$A27,YouTube_Shorts!B:B,$B27)) | I27: =IF($A27="","",SUMIFS(YouTube_Shorts!G:G,YouTube_Shorts!A:A,$A27,YouTube_Shorts!B:B,$B27)) | J27: =IF($A27="","",$D27+$H27) | K27: =IF($A27="","",SUMIFS(Audio!D:D,Audio!A:A,$A27,Audio!B:B,$B27)) | L27: =IF($A27="","",COUNTIFS(TikTok_Posts!A:A,$A27,TikTok_Posts!B:B,$B27)) | M27: =IF($A27="","",SUMIFS(TikTok_Posts!E:E,TikTok_Posts!A:A,$A27,TikTok_Posts!B:B,$B27)) | N27: =IF($A27="","",COUNTIFS(Instagram_Posts!A:A,$A27,Instagram_Posts!B:B,$B27)) | O27: =IF($A27="","",SUMIFS(Instagram_Posts!E:E,Instagram_Posts!A:A,$A27,Instagram_Posts!B:B,$B27)) | P27: =IF($A27="","",SUMIFS(Blog!E:E,Blog!B:B,$A27,Blog!C:C,$B27)) | Q27: =IF($A27="","",COUNTIFS(LinkedIn_Posts!A:A,$A27,LinkedIn_Posts!B:B,$B27)) | R27: =IF($A27="","",SUMIFS(LinkedIn_Posts!F:F,LinkedIn_Posts!A:A,$A27,LinkedIn_Posts!B:B,$B27)) | S27: =IF($A27="","",SUMIFS(LinkedIn_Posts!G:G,LinkedIn_Posts!A:A,$A27,LinkedIn_Posts!B:B,$B27)) | T27: =IF($A27="","",SUMIFS(LinkedIn_Posts!H:H,LinkedIn_Posts!A:A,$A27,LinkedIn_Posts!B:B,$B27)) | U27: =IF($A27="","",SUMIFS(LinkedIn_Posts!I:I,LinkedIn_Posts!A:A,$A27,LinkedIn_Posts!B:B,$B27))
D28: =IF($A28="","",SUMIFS(YouTube_Long!G:G,YouTube_Long!A:A,$A28,YouTube_Long!B:B,$B28)) | E28: =IF($A28="","",SUMIFS(YouTube_Long!H:H,YouTube_Long!A:A,$A28,YouTube_Long!B:B,$B28)) | F28: =IF($A28="","",SUMIFS(YouTube_Long!I:I,YouTube_Long!A:A,$A28,YouTube_Long!B:B,$B28)) | G28: =IF($A28="","",COUNTIFS(YouTube_Shorts!A:A,$A28,YouTube_Shorts!B:B,$B28)) | H28: =IF($A28="","",SUMIFS(YouTube_Shorts!F:F,YouTube_Shorts!A:A,$A28,YouTube_Shorts!B:B,$B28)) | I28: =IF($A28="","",SUMIFS(YouTube_Shorts!G:G,YouTube_Shorts!A:A,$A28,YouTube_Shorts!B:B,$B28)) | J28: =IF($A28="","",$D28+$H28) | K28: =IF($A28="","",SUMIFS(Audio!D:D,Audio!A:A,$A28,Audio!B:B,$B28)) | L28: =IF($A28="","",COUNTIFS(TikTok_Posts!A:A,$A28,TikTok_Posts!B:B,$B28)) | M28: =IF($A28="","",SUMIFS(TikTok_Posts!E:E,TikTok_Posts!A:A,$A28,TikTok_Posts!B:B,$B28)) | N28: =IF($A28="","",COUNTIFS(Instagram_Posts!A:A,$A28,Instagram_Posts!B:B,$B28)) | O28: =IF($A28="","",SUMIFS(Instagram_Posts!E:E,Instagram_Posts!A:A,$A28,Instagram_Posts!B:B,$B28)) | P28: =IF($A28="","",SUMIFS(Blog!E:E,Blog!B:B,$A28,Blog!C:C,$B28)) | Q28: =IF($A28="","",COUNTIFS(LinkedIn_Posts!A:A,$A28,LinkedIn_Posts!B:B,$B28)) | R28: =IF($A28="","",SUMIFS(LinkedIn_Posts!F:F,LinkedIn_Posts!A:A,$A28,LinkedIn_Posts!B:B,$B28)) | S28: =IF($A28="","",SUMIFS(LinkedIn_Posts!G:G,LinkedIn_Posts!A:A,$A28,LinkedIn_Posts!B:B,$B28)) | T28: =IF($A28="","",SUMIFS(LinkedIn_Posts!H:H,LinkedIn_Posts!A:A,$A28,LinkedIn_Posts!B:B,$B28)) | U28: =IF($A28="","",SUMIFS(LinkedIn_Posts!I:I,LinkedIn_Posts!A:A,$A28,LinkedIn_Posts!B:B,$B28))
D29: =IF($A29="","",SUMIFS(YouTube_Long!G:G,YouTube_Long!A:A,$A29,YouTube_Long!B:B,$B29)) | E29: =IF($A29="","",SUMIFS(YouTube_Long!H:H,YouTube_Long!A:A,$A29,YouTube_Long!B:B,$B29)) | F29: =IF($A29="","",SUMIFS(YouTube_Long!I:I,YouTube_Long!A:A,$A29,YouTube_Long!B:B,$B29)) | G29: =IF($A29="","",COUNTIFS(YouTube_Shorts!A:A,$A29,YouTube_Shorts!B:B,$B29)) | H29: =IF($A29="","",SUMIFS(YouTube_Shorts!F:F,YouTube_Shorts!A:A,$A29,YouTube_Shorts!B:B,$B29)) | I29: =IF($A29="","",SUMIFS(YouTube_Shorts!G:G,YouTube_Shorts!A:A,$A29,YouTube_Shorts!B:B,$B29)) | J29: =IF($A29="","",$D29+$H29) | K29: =IF($A29="","",SUMIFS(Audio!D:D,Audio!A:A,$A29,Audio!B:B,$B29)) | L29: =IF($A29="","",COUNTIFS(TikTok_Posts!A:A,$A29,TikTok_Posts!B:B,$B29)) | M29: =IF($A29="","",SUMIFS(TikTok_Posts!E:E,TikTok_Posts!A:A,$A29,TikTok_Posts!B:B,$B29)) | N29: =IF($A29="","",COUNTIFS(Instagram_Posts!A:A,$A29,Instagram_Posts!B:B,$B29)) | O29: =IF($A29="","",SUMIFS(Instagram_Posts!E:E,Instagram_Posts!A:A,$A29,Instagram_Posts!B:B,$B29)) | P29: =IF($A29="","",SUMIFS(Blog!E:E,Blog!B:B,$A29,Blog!C:C,$B29)) | Q29: =IF($A29="","",COUNTIFS(LinkedIn_Posts!A:A,$A29,LinkedIn_Posts!B:B,$B29)) | R29: =IF($A29="","",SUMIFS(LinkedIn_Posts!F:F,LinkedIn_Posts!A:A,$A29,LinkedIn_Posts!B:B,$B29)) | S29: =IF($A29="","",SUMIFS(LinkedIn_Posts!G:G,LinkedIn_Posts!A:A,$A29,LinkedIn_Posts!B:B,$B29)) | T29: =IF($A29="","",SUMIFS(LinkedIn_Posts!H:H,LinkedIn_Posts!A:A,$A29,LinkedIn_Posts!B:B,$B29)) | U29: =IF($A29="","",SUMIFS(LinkedIn_Posts!I:I,LinkedIn_Posts!A:A,$A29,LinkedIn_Posts!B:B,$B29))
D30: =IF($A30="","",SUMIFS(YouTube_Long!G:G,YouTube_Long!A:A,$A30,YouTube_Long!B:B,$B30)) | E30: =IF($A30="","",SUMIFS(YouTube_Long!H:H,YouTube_Long!A:A,$A30,YouTube_Long!B:B,$B30)) | F30: =IF($A30="","",SUMIFS(YouTube_Long!I:I,YouTube_Long!A:A,$A30,YouTube_Long!B:B,$B30)) | G30: =IF($A30="","",COUNTIFS(YouTube_Shorts!A:A,$A30,YouTube_Shorts!B:B,$B30)) | H30: =IF($A30="","",SUMIFS(YouTube_Shorts!F:F,YouTube_Shorts!A:A,$A30,YouTube_Shorts!B:B,$B30)) | I30: =IF($A30="","",SUMIFS(YouTube_Shorts!G:G,YouTube_Shorts!A:A,$A30,YouTube_Shorts!B:B,$B30)) | J30: =IF($A30="","",$D30+$H30) | K30: =IF($A30="","",SUMIFS(Audio!D:D,Audio!A:A,$A30,Audio!B:B,$B30)) | L30: =IF($A30="","",COUNTIFS(TikTok_Posts!A:A,$A30,TikTok_Posts!B:B,$B30)) | M30: =IF($A30="","",SUMIFS(TikTok_Posts!E:E,TikTok_Posts!A:A,$A30,TikTok_Posts!B:B,$B30)) | N30: =IF($A30="","",COUNTIFS(Instagram_Posts!A:A,$A30,Instagram_Posts!B:B,$B30)) | O30: =IF($A30="","",SUMIFS(Instagram_Posts!E:E,Instagram_Posts!A:A,$A30,Instagram_Posts!B:B,$B30)) | P30: =IF($A30="","",SUMIFS(Blog!E:E,Blog!B:B,$A30,Blog!C:C,$B30)) | Q30: =IF($A30="","",COUNTIFS(LinkedIn_Posts!A:A,$A30,LinkedIn_Posts!B:B,$B30)) | R30: =IF($A30="","",SUMIFS(LinkedIn_Posts!F:F,LinkedIn_Posts!A:A,$A30,LinkedIn_Posts!B:B,$B30)) | S30: =IF($A30="","",SUMIFS(LinkedIn_Posts!G:G,LinkedIn_Posts!A:A,$A30,LinkedIn_Posts!B:B,$B30)) | T30: =IF($A30="","",SUMIFS(LinkedIn_Posts!H:H,LinkedIn_Posts!A:A,$A30,LinkedIn_Posts!B:B,$B30)) | U30: =IF($A30="","",SUMIFS(LinkedIn_Posts!I:I,LinkedIn_Posts!A:A,$A30,LinkedIn_Posts!B:B,$B30))
D31: =IF($A31="","",SUMIFS(YouTube_Long!G:G,YouTube_Long!A:A,$A31,YouTube_Long!B:B,$B31)) | E31: =IF($A31="","",SUMIFS(YouTube_Long!H:H,YouTube_Long!A:A,$A31,YouTube_Long!B:B,$B31)) | F31: =IF($A31="","",SUMIFS(YouTube_Long!I:I,YouTube_Long!A:A,$A31,YouTube_Long!B:B,$B31)) | G31: =IF($A31="","",COUNTIFS(YouTube_Shorts!A:A,$A31,YouTube_Shorts!B:B,$B31)) | H31: =IF($A31="","",SUMIFS(YouTube_Shorts!F:F,YouTube_Shorts!A:A,$A31,YouTube_Shorts!B:B,$B31)) | I31: =IF($A31="","",SUMIFS(YouTube_Shorts!G:G,YouTube_Shorts!A:A,$A31,YouTube_Shorts!B:B,$B31)) | J31: =IF($A31="","",$D31+$H31) | K31: =IF($A31="","",SUMIFS(Audio!D:D,Audio!A:A,$A31,Audio!B:B,$B31)) | L31: =IF($A31="","",COUNTIFS(TikTok_Posts!A:A,$A31,TikTok_Posts!B:B,$B31)) | M31: =IF($A31="","",SUMIFS(TikTok_Posts!E:E,TikTok_Posts!A:A,$A31,TikTok_Posts!B:B,$B31)) | N31: =IF($A31="","",COUNTIFS(Instagram_Posts!A:A,$A31,Instagram_Posts!B:B,$B31)) | O31: =IF($A31="","",SUMIFS(Instagram_Posts!E:E,Instagram_Posts!A:A,$A31,Instagram_Posts!B:B,$B31)) | P31: =IF($A31="","",SUMIFS(Blog!E:E,Blog!B:B,$A31,Blog!C:C,$B31)) | Q31: =IF($A31="","",COUNTIFS(LinkedIn_Posts!A:A,$A31,LinkedIn_Posts!B:B,$B31)) | R31: =IF($A31="","",SUMIFS(LinkedIn_Posts!F:F,LinkedIn_Posts!A:A,$A31,LinkedIn_Posts!B:B,$B31)) | S31: =IF($A31="","",SUMIFS(LinkedIn_Posts!G:G,LinkedIn_Posts!A:A,$A31,LinkedIn_Posts!B:B,$B31)) | T31: =IF($A31="","",SUMIFS(LinkedIn_Posts!H:H,LinkedIn_Posts!A:A,$A31,LinkedIn_Posts!B:B,$B31)) | U31: =IF($A31="","",SUMIFS(LinkedIn_Posts!I:I,LinkedIn_Posts!A:A,$A31,LinkedIn_Posts!B:B,$B31))
